pythagor@0 BGE_small_fine_tune % python train_bge_small.py 
/Users/pythagor/nexus/.venv/lib/python3.9/site-packages/urllib3/__init__.py:35: NotOpenSSLWarning: urllib3 v2 only supports OpenSSL 1.1.1+, currently the 'ssl' module is compiled with 'LibreSSL 2.8.3'. See: https://github.com/urllib3/urllib3/issues/3020
  warnings.warn(
2025-03-19 17:17:55 - Using data file: BGE_small_training_triplets.json
2025-03-19 17:17:55 - Loading triplets from BGE_small_training_triplets.json
2025-03-19 17:17:55 - Loaded 14917 triplets
2025-03-19 17:17:55 - Created 14917 training examples
2025-03-19 17:17:55 - Splitting data: 13426 training, 1491 evaluation examples
2025-03-19 17:17:55 - Output will be saved to bge_small_finetuned_20250319_171755
2025-03-19 17:17:55 - Loading model from /Users/pythagor/.lmstudio/models/CompendiumLabs/bge-small-en-v1.5-gguf/bge-small-en-v1.5-f32.gguf
2025-03-19 17:17:55 - Use pytorch device_name: mps
2025-03-19 17:17:55 - Load pretrained SentenceTransformer: /Users/pythagor/.lmstudio/models/CompendiumLabs/bge-small-en-v1.5-gguf/bge-small-en-v1.5-f32.gguf
2025-03-19 17:17:55 - No sentence-transformers model found with name /Users/pythagor/.lmstudio/models/CompendiumLabs/bge-small-en-v1.5-gguf/bge-small-en-v1.5-f32.gguf. Creating a new one with mean pooling.
Traceback (most recent call last):
  File "/Users/pythagor/nexus/.venv/lib/python3.9/site-packages/transformers/utils/hub.py", line 342, in cached_file
    resolved_file = hf_hub_download(
  File "/Users/pythagor/nexus/.venv/lib/python3.9/site-packages/huggingface_hub/utils/_validators.py", line 106, in _inner_fn
    validate_repo_id(arg_value)
  File "/Users/pythagor/nexus/.venv/lib/python3.9/site-packages/huggingface_hub/utils/_validators.py", line 154, in validate_repo_id
    raise HFValidationError(
huggingface_hub.errors.HFValidationError: Repo id must be in the form 'repo_name' or 'namespace/repo_name': '/Users/pythagor/.lmstudio/models/CompendiumLabs/bge-small-en-v1.5-gguf/bge-small-en-v1.5-f32.gguf'. Use `repo_type` argument if needed.

The above exception was the direct cause of the following exception:

Traceback (most recent call last):
  File "/Users/pythagor/nexus/echo/BGE_small_fine_tune/train_bge_small.py", line 195, in <module>
    main()
  File "/Users/pythagor/nexus/echo/BGE_small_fine_tune/train_bge_small.py", line 184, in main
    fine_tune_model(
  File "/Users/pythagor/nexus/echo/BGE_small_fine_tune/train_bge_small.py", line 107, in fine_tune_model
    model = SentenceTransformer(model_path)
  File "/Users/pythagor/nexus/.venv/lib/python3.9/site-packages/sentence_transformers/SentenceTransformer.py", line 320, in __init__
    modules = self._load_auto_model(
  File "/Users/pythagor/nexus/.venv/lib/python3.9/site-packages/sentence_transformers/SentenceTransformer.py", line 1538, in _load_auto_model
    transformer_model = Transformer(
  File "/Users/pythagor/nexus/.venv/lib/python3.9/site-packages/sentence_transformers/models/Transformer.py", line 80, in __init__
    config, is_peft_model = self._load_config(model_name_or_path, cache_dir, backend, config_args)
  File "/Users/pythagor/nexus/.venv/lib/python3.9/site-packages/sentence_transformers/models/Transformer.py", line 121, in _load_config
    find_adapter_config_file(
  File "/Users/pythagor/nexus/.venv/lib/python3.9/site-packages/transformers/utils/peft_utils.py", line 88, in find_adapter_config_file
    adapter_cached_filename = cached_file(
  File "/Users/pythagor/nexus/.venv/lib/python3.9/site-packages/transformers/utils/hub.py", line 408, in cached_file
    raise EnvironmentError(
OSError: Incorrect path_or_model_id: '/Users/pythagor/.lmstudio/models/CompendiumLabs/bge-small-en-v1.5-gguf/bge-small-en-v1.5-f32.gguf'. Please provide either the path to a local folder or the repo_id of a model on the Hub.